<?xml version='1.0'?>
<sdf version='1.7'>
  <model name='uav0'>
    <link name='base_link'>
      <inertial>
        <pose>0 0 0 0 -0 0</pose>
        <mass>2</mass>
        <inertia>
          <ixx>0.0316667</ixx>
          <ixy>0</ixy>
          <ixz>0</ixz>
          <iyy>0.0316667</iyy>
          <iyz>0</iyz>
          <izz>0.0625</izz>
        </inertia>
      </inertial>
      <self_collide>0</self_collide>
      <enable_wind>0</enable_wind>
      <kinematic>0</kinematic>
      <pose>0 0 0 0 -0 0</pose>
      <visual name='base_link_fixed_joint_lump__back_left_arm_link_visual'>
        <pose>0 0 0 0 -0 2.35619</pose>
        <geometry>
          <mesh>
            <scale>1 1 1</scale>
            <uri>model://mrs_robots_description/meshes/holybro/holybro_x500_arm.dae</uri>
          </mesh>
        </geometry>
        <material>
          <script>
            <name>Gazebo/DarkGrey</name>
            <uri>file://media/materials/scripts/gazebo.material</uri>
          </script>
          <shader type='pixel'/>
        </material>
        <transparency>0</transparency>
        <cast_shadows>1</cast_shadows>
      </visual>
      <visual name='base_link_fixed_joint_lump__back_left_rotor_link_visual_1'>
        <pose>-0.177484 0.177484 0.021 0 -0 0</pose>
        <geometry>
          <mesh>
            <scale>1 1 1</scale>
            <uri>model://mrs_robots_description/meshes/holybro/holybro_x500_motor.dae</uri>
          </mesh>
        </geometry>
        <material>
          <script>
            <name>Gazebo/DarkGrey</name>
            <uri>file://media/materials/scripts/gazebo.material</uri>
          </script>
          <shader type='pixel'/>
        </material>
        <transparency>0</transparency>
        <cast_shadows>1</cast_shadows>
      </visual>
      <visual name='base_link_fixed_joint_lump__back_right_arm_link_visual_2'>
        <pose>0 0 0 0 0 -2.35619</pose>
        <geometry>
          <mesh>
            <scale>1 1 1</scale>
            <uri>model://mrs_robots_description/meshes/holybro/holybro_x500_arm.dae</uri>
          </mesh>
        </geometry>
        <material>
          <script>
            <name>Gazebo/DarkGrey</name>
            <uri>file://media/materials/scripts/gazebo.material</uri>
          </script>
          <shader type='pixel'/>
        </material>
        <transparency>0</transparency>
        <cast_shadows>1</cast_shadows>
      </visual>
      <visual name='base_link_fixed_joint_lump__back_right_rotor_link_visual_3'>
        <pose>-0.177484 -0.177484 0.021 0 -0 0</pose>
        <geometry>
          <mesh>
            <scale>1 1 1</scale>
            <uri>model://mrs_robots_description/meshes/holybro/holybro_x500_motor.dae</uri>
          </mesh>
        </geometry>
        <material>
          <script>
            <name>Gazebo/DarkGrey</name>
            <uri>file://media/materials/scripts/gazebo.material</uri>
          </script>
          <shader type='pixel'/>
        </material>
        <transparency>0</transparency>
        <cast_shadows>1</cast_shadows>
      </visual>
      <visual name='base_link_fixed_joint_lump__battery_mount_link_visual_4'>
        <pose>0 0 0 0 -0 0</pose>
        <geometry>
          <mesh>
            <scale>1 1 1</scale>
            <uri>model://mrs_robots_description/meshes/holybro/holybro_x500_battery.dae</uri>
          </mesh>
        </geometry>
        <material>
          <script>
            <name>Gazebo/DarkGrey</name>
            <uri>file://media/materials/scripts/gazebo.material</uri>
          </script>
          <shader type='pixel'/>
        </material>
        <transparency>0</transparency>
        <cast_shadows>1</cast_shadows>
      </visual>
      <visual name='base_link_fixed_joint_lump__bottom_board_link_visual_5'>
        <pose>0 0 0 0 -0 0</pose>
        <geometry>
          <mesh>
            <scale>1 1 1</scale>
            <uri>model://mrs_robots_description/meshes/holybro/holybro_x500_bottom_board.dae</uri>
          </mesh>
        </geometry>
        <material>
          <script>
            <name>Gazebo/DarkGrey</name>
            <uri>file://media/materials/scripts/gazebo.material</uri>
          </script>
          <shader type='pixel'/>
        </material>
        <transparency>0</transparency>
        <cast_shadows>1</cast_shadows>
      </visual>
      <visual name='base_link_fixed_joint_lump__computer_board_link_visual_6'>
        <pose>0 0 0.058 0 -0 0</pose>
        <geometry>
          <box>
            <size>0.125 0.125 0.002</size>
          </box>
        </geometry>
        <material>
          <script>
            <name>Gazebo/Grass</name>
            <uri>file://media/materials/scripts/gazebo.material</uri>
          </script>
          <shader type='pixel'/>
        </material>
        <transparency>0</transparency>
        <cast_shadows>1</cast_shadows>
      </visual>
      <visual name='base_link_fixed_joint_lump__computer_heatsink_link_visual_7'>
        <pose>0.009 0.012 0.074 0 -0 0</pose>
        <geometry>
          <box>
            <size>0.071 0.071 0.027</size>
          </box>
        </geometry>
        <material>
          <script>
            <name>Gazebo/Grey</name>
            <uri>file://media/materials/scripts/gazebo.material</uri>
          </script>
          <shader type='pixel'/>
        </material>
        <transparency>0</transparency>
        <cast_shadows>1</cast_shadows>
      </visual>
      <visual name='base_link_fixed_joint_lump__front_left_arm_link_visual_8'>
        <pose>0 0 0 0 -0 0.785398</pose>
        <geometry>
          <mesh>
            <scale>1 1 1</scale>
            <uri>model://mrs_robots_description/meshes/holybro/holybro_x500_arm.dae</uri>
          </mesh>
        </geometry>
        <material>
          <script>
            <name>Gazebo/DarkGrey</name>
            <uri>file://media/materials/scripts/gazebo.material</uri>
          </script>
          <shader type='pixel'/>
        </material>
        <transparency>0</transparency>
        <cast_shadows>1</cast_shadows>
      </visual>
      <visual name='base_link_fixed_joint_lump__front_left_leg_clip_link_visual_9'>
        <pose>0.162635 0.162635 -0.157 0 -0 0.785398</pose>
        <geometry>
          <mesh>
            <scale>1 1 1</scale>
            <uri>model://mrs_robots_description/meshes/holybro/holybro_x500_leg.dae</uri>
          </mesh>
        </geometry>
        <material>
          <script>
            <name>Gazebo/DarkGrey</name>
            <uri>file://media/materials/scripts/gazebo.material</uri>
          </script>
          <shader type='pixel'/>
        </material>
        <transparency>0</transparency>
        <cast_shadows>1</cast_shadows>
      </visual>
      <visual name='base_link_fixed_joint_lump__front_left_rotor_link_visual_10'>
        <pose>0.177484 0.177484 0.021 0 -0 0</pose>
        <geometry>
          <mesh>
            <scale>1 1 1</scale>
            <uri>model://mrs_robots_description/meshes/holybro/holybro_x500_motor.dae</uri>
          </mesh>
        </geometry>
        <material>
          <script>
            <name>Gazebo/DarkGrey</name>
            <uri>file://media/materials/scripts/gazebo.material</uri>
          </script>
          <shader type='pixel'/>
        </material>
        <transparency>0</transparency>
        <cast_shadows>1</cast_shadows>
      </visual>
      <visual name='base_link_fixed_joint_lump__front_right_arm_link_visual_11'>
        <pose>0 0 0 0 0 -0.785398</pose>
        <geometry>
          <mesh>
            <scale>1 1 1</scale>
            <uri>model://mrs_robots_description/meshes/holybro/holybro_x500_arm.dae</uri>
          </mesh>
        </geometry>
        <material>
          <script>
            <name>Gazebo/DarkGrey</name>
            <uri>file://media/materials/scripts/gazebo.material</uri>
          </script>
          <shader type='pixel'/>
        </material>
        <transparency>0</transparency>
        <cast_shadows>1</cast_shadows>
      </visual>
      <visual name='base_link_fixed_joint_lump__front_right_leg_clip_link_visual_12'>
        <pose>0.162635 -0.162635 -0.157 0 0 -0.785398</pose>
        <geometry>
          <mesh>
            <scale>1 1 1</scale>
            <uri>model://mrs_robots_description/meshes/holybro/holybro_x500_leg.dae</uri>
          </mesh>
        </geometry>
        <material>
          <script>
            <name>Gazebo/DarkGrey</name>
            <uri>file://media/materials/scripts/gazebo.material</uri>
          </script>
          <shader type='pixel'/>
        </material>
        <transparency>0</transparency>
        <cast_shadows>1</cast_shadows>
      </visual>
      <visual name='base_link_fixed_joint_lump__front_right_rotor_link_visual_13'>
        <pose>0.177484 -0.177484 0.021 0 -0 0</pose>
        <geometry>
          <mesh>
            <scale>1 1 1</scale>
            <uri>model://mrs_robots_description/meshes/holybro/holybro_x500_motor.dae</uri>
          </mesh>
        </geometry>
        <material>
          <script>
            <name>Gazebo/DarkGrey</name>
            <uri>file://media/materials/scripts/gazebo.material</uri>
          </script>
          <shader type='pixel'/>
        </material>
        <transparency>0</transparency>
        <cast_shadows>1</cast_shadows>
      </visual>
      <visual name='base_link_fixed_joint_lump__pc_mount_link_visual_14'>
        <pose>0 0 0 0 -0 0</pose>
        <geometry>
          <mesh>
            <scale>1 1 1</scale>
            <uri>model://mrs_robots_description/meshes/holybro/holybro_x500_pc_mount.dae</uri>
          </mesh>
        </geometry>
        <material>
          <script>
            <name>Gazebo/Default</name>
            <uri>file://media/materials/scripts/gazebo.material</uri>
          </script>
          <shader type='pixel'/>
        </material>
        <transparency>0</transparency>
        <cast_shadows>1</cast_shadows>
      </visual>
      <visual name='base_link_fixed_joint_lump__pixhawk_link_visual_15'>
        <pose>0 0 -0.0075 0 -0 0</pose>
        <geometry>
          <mesh>
            <scale>1 1 1</scale>
            <uri>model://mrs_robots_description/meshes/sensors/pixhawk.dae</uri>
          </mesh>
        </geometry>
        <material>
          <script>
            <name>Gazebo/DarkGrey</name>
            <uri>file://media/materials/scripts/gazebo.material</uri>
          </script>
          <shader type='pixel'/>
        </material>
        <transparency>0</transparency>
        <cast_shadows>1</cast_shadows>
      </visual>
      <visual name='base_link_fixed_joint_lump__rear_left_leg_clip_link_visual_16'>
        <pose>-0.162635 0.162635 -0.157 0 -0 2.35619</pose>
        <geometry>
          <mesh>
            <scale>1 1 1</scale>
            <uri>model://mrs_robots_description/meshes/holybro/holybro_x500_leg.dae</uri>
          </mesh>
        </geometry>
        <material>
          <script>
            <name>Gazebo/Default</name>
            <uri>file://media/materials/scripts/gazebo.material</uri>
          </script>
          <shader type='pixel'/>
        </material>
        <transparency>0</transparency>
        <cast_shadows>1</cast_shadows>
      </visual>
      <visual name='base_link_fixed_joint_lump__rear_right_leg_clip_link_visual_17'>
        <pose>-0.162635 -0.162635 -0.157 0 0 -2.35619</pose>
        <geometry>
          <mesh>
            <scale>1 1 1</scale>
            <uri>model://mrs_robots_description/meshes/holybro/holybro_x500_leg.dae</uri>
          </mesh>
        </geometry>
        <material>
          <script>
            <name>Gazebo/Default</name>
            <uri>file://media/materials/scripts/gazebo.material</uri>
          </script>
          <shader type='pixel'/>
        </material>
        <transparency>0</transparency>
        <cast_shadows>1</cast_shadows>
      </visual>
      <visual name='base_link_fixed_joint_lump__top_board_link_visual_18'>
        <pose>0 0 0 0 -0 0</pose>
        <geometry>
          <mesh>
            <scale>1 1 1</scale>
            <uri>model://mrs_robots_description/meshes/holybro/holybro_x500_top_board.dae</uri>
          </mesh>
        </geometry>
        <material>
          <script>
            <name>Gazebo/DarkGrey</name>
            <uri>file://media/materials/scripts/gazebo.material</uri>
          </script>
          <shader type='pixel'/>
        </material>
        <transparency>0</transparency>
        <cast_shadows>1</cast_shadows>
      </visual>
      <collision name='base_link_inertia_collision'>
        <laser_retro>0</laser_retro>
        <max_contacts>10</max_contacts>
        <pose>0 0 0 0 -0 0</pose>
        <geometry>
          <cylinder>
            <radius>0.275</radius>
            <length>0.15</length>
          </cylinder>
        </geometry>
        <surface>
          <friction>
            <ode>
              <mu>1</mu>
              <mu2>1</mu2>
              <fdir1>0 0 0</fdir1>
              <slip1>0</slip1>
              <slip2>0</slip2>
            </ode>
            <torsional>
              <coefficient>1</coefficient>
              <patch_radius>0</patch_radius>
              <surface_radius>0</surface_radius>
              <use_patch_radius>1</use_patch_radius>
              <ode>
                <slip>0</slip>
              </ode>
            </torsional>
          </friction>
          <bounce>
            <restitution_coefficient>0</restitution_coefficient>
            <threshold>1e+06</threshold>
          </bounce>
          <contact>
            <collide_without_contact>0</collide_without_contact>
            <collide_without_contact_bitmask>1</collide_without_contact_bitmask>
            <collide_bitmask>1</collide_bitmask>
            <ode>
              <soft_cfm>0</soft_cfm>
              <soft_erp>0.2</soft_erp>
              <kp>1e+13</kp>
              <kd>1</kd>
              <max_vel>0</max_vel>
              <min_depth>0.001</min_depth>
            </ode>
            <bullet>
              <split_impulse>1</split_impulse>
              <split_impulse_penetration_threshold>-0.01</split_impulse_penetration_threshold>
              <soft_cfm>0</soft_cfm>
              <soft_erp>0.2</soft_erp>
              <kp>1e+13</kp>
              <kd>1</kd>
            </bullet>
          </contact>
        </surface>
      </collision>
      <collision name='base_link_fixed_joint_lump__front_left_leg_clip_link_collision_1'>
        <laser_retro>0</laser_retro>
        <max_contacts>10</max_contacts>
        <pose>0.162635 0.162635 -0.0785 0 -0 0</pose>
        <geometry>
          <cylinder>
            <radius>0.012</radius>
            <length>0.157</length>
          </cylinder>
        </geometry>
        <surface>
          <friction>
            <ode>
              <mu>1</mu>
              <mu2>1</mu2>
              <fdir1>0 0 0</fdir1>
              <slip1>0</slip1>
              <slip2>0</slip2>
            </ode>
            <torsional>
              <coefficient>1</coefficient>
              <patch_radius>0</patch_radius>
              <surface_radius>0</surface_radius>
              <use_patch_radius>1</use_patch_radius>
              <ode>
                <slip>0</slip>
              </ode>
            </torsional>
          </friction>
          <bounce>
            <restitution_coefficient>0</restitution_coefficient>
            <threshold>1e+06</threshold>
          </bounce>
          <contact>
            <collide_without_contact>0</collide_without_contact>
            <collide_without_contact_bitmask>1</collide_without_contact_bitmask>
            <collide_bitmask>1</collide_bitmask>
            <ode>
              <soft_cfm>0</soft_cfm>
              <soft_erp>0.2</soft_erp>
              <kp>1e+13</kp>
              <kd>1</kd>
              <max_vel>0</max_vel>
              <min_depth>0.001</min_depth>
            </ode>
            <bullet>
              <split_impulse>1</split_impulse>
              <split_impulse_penetration_threshold>-0.01</split_impulse_penetration_threshold>
              <soft_cfm>0</soft_cfm>
              <soft_erp>0.2</soft_erp>
              <kp>1e+13</kp>
              <kd>1</kd>
            </bullet>
          </contact>
        </surface>
      </collision>
      <collision name='base_link_fixed_joint_lump__front_right_leg_clip_link_collision_2'>
        <laser_retro>0</laser_retro>
        <max_contacts>10</max_contacts>
        <pose>0.162635 -0.162635 -0.0785 0 0 -1.5708</pose>
        <geometry>
          <cylinder>
            <radius>0.012</radius>
            <length>0.157</length>
          </cylinder>
        </geometry>
        <surface>
          <friction>
            <ode>
              <mu>1</mu>
              <mu2>1</mu2>
              <fdir1>0 0 0</fdir1>
              <slip1>0</slip1>
              <slip2>0</slip2>
            </ode>
            <torsional>
              <coefficient>1</coefficient>
              <patch_radius>0</patch_radius>
              <surface_radius>0</surface_radius>
              <use_patch_radius>1</use_patch_radius>
              <ode>
                <slip>0</slip>
              </ode>
            </torsional>
          </friction>
          <bounce>
            <restitution_coefficient>0</restitution_coefficient>
            <threshold>1e+06</threshold>
          </bounce>
          <contact>
            <collide_without_contact>0</collide_without_contact>
            <collide_without_contact_bitmask>1</collide_without_contact_bitmask>
            <collide_bitmask>1</collide_bitmask>
            <ode>
              <soft_cfm>0</soft_cfm>
              <soft_erp>0.2</soft_erp>
              <kp>1e+13</kp>
              <kd>1</kd>
              <max_vel>0</max_vel>
              <min_depth>0.001</min_depth>
            </ode>
            <bullet>
              <split_impulse>1</split_impulse>
              <split_impulse_penetration_threshold>-0.01</split_impulse_penetration_threshold>
              <soft_cfm>0</soft_cfm>
              <soft_erp>0.2</soft_erp>
              <kp>1e+13</kp>
              <kd>1</kd>
            </bullet>
          </contact>
        </surface>
      </collision>
      <collision name='base_link_fixed_joint_lump__rear_left_leg_clip_link_collision_3'>
        <laser_retro>0</laser_retro>
        <max_contacts>10</max_contacts>
        <pose>-0.162635 0.162635 -0.0785 0 -0 1.5708</pose>
        <geometry>
          <cylinder>
            <radius>0.012</radius>
            <length>0.157</length>
          </cylinder>
        </geometry>
        <surface>
          <friction>
            <ode>
              <mu>1</mu>
              <mu2>1</mu2>
              <fdir1>0 0 0</fdir1>
              <slip1>0</slip1>
              <slip2>0</slip2>
            </ode>
            <torsional>
              <coefficient>1</coefficient>
              <patch_radius>0</patch_radius>
              <surface_radius>0</surface_radius>
              <use_patch_radius>1</use_patch_radius>
              <ode>
                <slip>0</slip>
              </ode>
            </torsional>
          </friction>
          <bounce>
            <restitution_coefficient>0</restitution_coefficient>
            <threshold>1e+06</threshold>
          </bounce>
          <contact>
            <collide_without_contact>0</collide_without_contact>
            <collide_without_contact_bitmask>1</collide_without_contact_bitmask>
            <collide_bitmask>1</collide_bitmask>
            <ode>
              <soft_cfm>0</soft_cfm>
              <soft_erp>0.2</soft_erp>
              <kp>1e+13</kp>
              <kd>1</kd>
              <max_vel>0</max_vel>
              <min_depth>0.001</min_depth>
            </ode>
            <bullet>
              <split_impulse>1</split_impulse>
              <split_impulse_penetration_threshold>-0.01</split_impulse_penetration_threshold>
              <soft_cfm>0</soft_cfm>
              <soft_erp>0.2</soft_erp>
              <kp>1e+13</kp>
              <kd>1</kd>
            </bullet>
          </contact>
        </surface>
      </collision>
      <collision name='base_link_fixed_joint_lump__rear_right_leg_clip_link_collision_4'>
        <laser_retro>0</laser_retro>
        <max_contacts>10</max_contacts>
        <pose>-0.162635 -0.162635 -0.0785 0 0 -3.14159</pose>
        <geometry>
          <cylinder>
            <radius>0.012</radius>
            <length>0.157</length>
          </cylinder>
        </geometry>
        <surface>
          <friction>
            <ode>
              <mu>1</mu>
              <mu2>1</mu2>
              <fdir1>0 0 0</fdir1>
              <slip1>0</slip1>
              <slip2>0</slip2>
            </ode>
            <torsional>
              <coefficient>1</coefficient>
              <patch_radius>0</patch_radius>
              <surface_radius>0</surface_radius>
              <use_patch_radius>1</use_patch_radius>
              <ode>
                <slip>0</slip>
              </ode>
            </torsional>
          </friction>
          <bounce>
            <restitution_coefficient>0</restitution_coefficient>
            <threshold>1e+06</threshold>
          </bounce>
          <contact>
            <collide_without_contact>0</collide_without_contact>
            <collide_without_contact_bitmask>1</collide_without_contact_bitmask>
            <collide_bitmask>1</collide_bitmask>
            <ode>
              <soft_cfm>0</soft_cfm>
              <soft_erp>0.2</soft_erp>
              <kp>1e+13</kp>
              <kd>1</kd>
              <max_vel>0</max_vel>
              <min_depth>0.001</min_depth>
            </ode>
            <bullet>
              <split_impulse>1</split_impulse>
              <split_impulse_penetration_threshold>-0.01</split_impulse_penetration_threshold>
              <soft_cfm>0</soft_cfm>
              <soft_erp>0.2</soft_erp>
              <kp>1e+13</kp>
              <kd>1</kd>
            </bullet>
          </contact>
        </surface>
      </collision>
    </link>
    <link name='gps0_link'>
      <pose>0 0 0 0 -0 0</pose>
      <inertial>
        <pose>0 0 0 0 -0 0</pose>
        <mass>0.01</mass>
        <inertia>
          <ixx>2.1733e-06</ixx>
          <ixy>0</ixy>
          <ixz>0</ixz>
          <iyy>2.1733e-06</iyy>
          <iyz>0</iyz>
          <izz>1.8e-07</izz>
        </inertia>
      </inertial>
      <sensor name='gps' type='gps'>
        <pose>0 0 0 0 -0 0</pose>
        <plugin name='gps_plugin' filename='libgazebo_gps_plugin.so'>
          <robotNamespace>uav0</robotNamespace>
          <gpsNoise>1</gpsNoise>
          <gpsXYRandomWalk>2.0</gpsXYRandomWalk>
          <gpsZRandomWalk>4.0</gpsZRandomWalk>
          <gpsXYNoiseDensity>0.0002</gpsXYNoiseDensity>
          <gpsZNoiseDensity>0.0004</gpsZNoiseDensity>
          <gpsVXYNoiseDensity>0.2</gpsVXYNoiseDensity>
          <gpsVZNoiseDensity>0.4</gpsVZNoiseDensity>
          <update_rate>10</update_rate>
          <topic>gps0</topic>
        </plugin>
        <gps/>
      </sensor>
      <self_collide>0</self_collide>
      <enable_wind>0</enable_wind>
      <kinematic>0</kinematic>
    </link>
    <link name='rotor_0'>
      <pose>0.177484 -0.177484 0.057 0 -0 0</pose>
      <inertial>
        <pose>0 0 0 0 -0 0</pose>
        <mass>0.005</mass>
        <inertia>
          <ixx>0.0001</ixx>
          <ixy>0</ixy>
          <ixz>0</ixz>
          <iyy>0.0001</iyy>
          <iyz>0</iyz>
          <izz>0.0001</izz>
        </inertia>
      </inertial>
      <self_collide>0</self_collide>
      <enable_wind>0</enable_wind>
      <kinematic>0</kinematic>
      <visual name='rotor_0_visual'>
        <pose>0 0 0 0 -0 0</pose>
        <geometry>
          <mesh>
            <scale>1 1 1</scale>
            <uri>model://mrs_robots_description/meshes/holybro/holybro_x500_prop.dae</uri>
          </mesh>
        </geometry>
        <material>
          <shader type='pixel'/>
        </material>
        <transparency>0</transparency>
        <cast_shadows>1</cast_shadows>
      </visual>
      <collision name='rotor_0_collision'>
        <laser_retro>0</laser_retro>
        <max_contacts>10</max_contacts>
        <pose>0 0 0 0 -0 0</pose>
        <geometry>
          <cylinder>
            <radius>0.127</radius>
            <length>0.005</length>
          </cylinder>
        </geometry>
        <surface>
          <friction>
            <ode>
              <mu>1</mu>
              <mu2>1</mu2>
              <fdir1>0 0 0</fdir1>
              <slip1>0</slip1>
              <slip2>0</slip2>
            </ode>
            <torsional>
              <coefficient>1</coefficient>
              <patch_radius>0</patch_radius>
              <surface_radius>0</surface_radius>
              <use_patch_radius>1</use_patch_radius>
              <ode>
                <slip>0</slip>
              </ode>
            </torsional>
          </friction>
          <bounce>
            <restitution_coefficient>0</restitution_coefficient>
            <threshold>1e+06</threshold>
          </bounce>
          <contact>
            <collide_without_contact>0</collide_without_contact>
            <collide_without_contact_bitmask>1</collide_without_contact_bitmask>
            <collide_bitmask>1</collide_bitmask>
            <ode>
              <soft_cfm>0</soft_cfm>
              <soft_erp>0.2</soft_erp>
              <kp>1e+13</kp>
              <kd>1</kd>
              <max_vel>0.01</max_vel>
              <min_depth>0</min_depth>
            </ode>
            <bullet>
              <split_impulse>1</split_impulse>
              <split_impulse_penetration_threshold>-0.01</split_impulse_penetration_threshold>
              <soft_cfm>0</soft_cfm>
              <soft_erp>0.2</soft_erp>
              <kp>1e+13</kp>
              <kd>1</kd>
            </bullet>
          </contact>
        </surface>
      </collision>
    </link>
    <link name='rotor_1'>
      <pose>-0.177484 0.177484 0.057 0 -0 0</pose>
      <inertial>
        <pose>0 0 0 0 -0 0</pose>
        <mass>0.005</mass>
        <inertia>
          <ixx>0.0001</ixx>
          <ixy>0</ixy>
          <ixz>0</ixz>
          <iyy>0.0001</iyy>
          <iyz>0</iyz>
          <izz>0.0001</izz>
        </inertia>
      </inertial>
      <self_collide>0</self_collide>
      <enable_wind>0</enable_wind>
      <kinematic>0</kinematic>
      <visual name='rotor_1_visual'>
        <pose>0 0 0 0 -0 0</pose>
        <geometry>
          <mesh>
            <scale>1 1 1</scale>
            <uri>model://mrs_robots_description/meshes/holybro/holybro_x500_prop.dae</uri>
          </mesh>
        </geometry>
        <material>
          <shader type='pixel'/>
        </material>
        <transparency>0</transparency>
        <cast_shadows>1</cast_shadows>
      </visual>
      <collision name='rotor_1_collision'>
        <laser_retro>0</laser_retro>
        <max_contacts>10</max_contacts>
        <pose>0 0 0 0 -0 0</pose>
        <geometry>
          <cylinder>
            <radius>0.127</radius>
            <length>0.005</length>
          </cylinder>
        </geometry>
        <surface>
          <friction>
            <ode>
              <mu>1</mu>
              <mu2>1</mu2>
              <fdir1>0 0 0</fdir1>
              <slip1>0</slip1>
              <slip2>0</slip2>
            </ode>
            <torsional>
              <coefficient>1</coefficient>
              <patch_radius>0</patch_radius>
              <surface_radius>0</surface_radius>
              <use_patch_radius>1</use_patch_radius>
              <ode>
                <slip>0</slip>
              </ode>
            </torsional>
          </friction>
          <bounce>
            <restitution_coefficient>0</restitution_coefficient>
            <threshold>1e+06</threshold>
          </bounce>
          <contact>
            <collide_without_contact>0</collide_without_contact>
            <collide_without_contact_bitmask>1</collide_without_contact_bitmask>
            <collide_bitmask>1</collide_bitmask>
            <ode>
              <soft_cfm>0</soft_cfm>
              <soft_erp>0.2</soft_erp>
              <kp>1e+13</kp>
              <kd>1</kd>
              <max_vel>0.01</max_vel>
              <min_depth>0</min_depth>
            </ode>
            <bullet>
              <split_impulse>1</split_impulse>
              <split_impulse_penetration_threshold>-0.01</split_impulse_penetration_threshold>
              <soft_cfm>0</soft_cfm>
              <soft_erp>0.2</soft_erp>
              <kp>1e+13</kp>
              <kd>1</kd>
            </bullet>
          </contact>
        </surface>
      </collision>
    </link>
    <link name='rotor_2'>
      <pose>0.177484 0.177484 0.057 0 -0 0</pose>
      <inertial>
        <pose>0 0 0 0 -0 0</pose>
        <mass>0.005</mass>
        <inertia>
          <ixx>0.0001</ixx>
          <ixy>0</ixy>
          <ixz>0</ixz>
          <iyy>0.0001</iyy>
          <iyz>0</iyz>
          <izz>0.0001</izz>
        </inertia>
      </inertial>
      <self_collide>0</self_collide>
      <enable_wind>0</enable_wind>
      <kinematic>0</kinematic>
      <visual name='rotor_2_visual'>
        <pose>0 0 0 0 -0 0</pose>
        <geometry>
          <mesh>
            <scale>-1 1 1</scale>
            <uri>model://mrs_robots_description/meshes/holybro/holybro_x500_prop.dae</uri>
          </mesh>
        </geometry>
        <material>
          <shader type='pixel'/>
        </material>
        <transparency>0</transparency>
        <cast_shadows>1</cast_shadows>
      </visual>
      <collision name='rotor_2_collision'>
        <laser_retro>0</laser_retro>
        <max_contacts>10</max_contacts>
        <pose>0 0 0 0 -0 0</pose>
        <geometry>
          <cylinder>
            <radius>0.127</radius>
            <length>0.005</length>
          </cylinder>
        </geometry>
        <surface>
          <friction>
            <ode>
              <mu>1</mu>
              <mu2>1</mu2>
              <fdir1>0 0 0</fdir1>
              <slip1>0</slip1>
              <slip2>0</slip2>
            </ode>
            <torsional>
              <coefficient>1</coefficient>
              <patch_radius>0</patch_radius>
              <surface_radius>0</surface_radius>
              <use_patch_radius>1</use_patch_radius>
              <ode>
                <slip>0</slip>
              </ode>
            </torsional>
          </friction>
          <bounce>
            <restitution_coefficient>0</restitution_coefficient>
            <threshold>1e+06</threshold>
          </bounce>
          <contact>
            <collide_without_contact>0</collide_without_contact>
            <collide_without_contact_bitmask>1</collide_without_contact_bitmask>
            <collide_bitmask>1</collide_bitmask>
            <ode>
              <soft_cfm>0</soft_cfm>
              <soft_erp>0.2</soft_erp>
              <kp>1e+13</kp>
              <kd>1</kd>
              <max_vel>0.01</max_vel>
              <min_depth>0</min_depth>
            </ode>
            <bullet>
              <split_impulse>1</split_impulse>
              <split_impulse_penetration_threshold>-0.01</split_impulse_penetration_threshold>
              <soft_cfm>0</soft_cfm>
              <soft_erp>0.2</soft_erp>
              <kp>1e+13</kp>
              <kd>1</kd>
            </bullet>
          </contact>
        </surface>
      </collision>
    </link>
    <link name='rotor_3'>
      <pose>-0.177484 -0.177484 0.057 0 -0 0</pose>
      <inertial>
        <pose>0 0 0 0 -0 0</pose>
        <mass>0.005</mass>
        <inertia>
          <ixx>0.0001</ixx>
          <ixy>0</ixy>
          <ixz>0</ixz>
          <iyy>0.0001</iyy>
          <iyz>0</iyz>
          <izz>0.0001</izz>
        </inertia>
      </inertial>
      <self_collide>0</self_collide>
      <enable_wind>0</enable_wind>
      <kinematic>0</kinematic>
      <visual name='rotor_3_visual'>
        <pose>0 0 0 0 -0 0</pose>
        <geometry>
          <mesh>
            <scale>-1 1 1</scale>
            <uri>model://mrs_robots_description/meshes/holybro/holybro_x500_prop.dae</uri>
          </mesh>
        </geometry>
        <material>
          <shader type='pixel'/>
        </material>
        <transparency>0</transparency>
        <cast_shadows>1</cast_shadows>
      </visual>
      <collision name='rotor_3_collision'>
        <laser_retro>0</laser_retro>
        <max_contacts>10</max_contacts>
        <pose>0 0 0 0 -0 0</pose>
        <geometry>
          <cylinder>
            <radius>0.127</radius>
            <length>0.005</length>
          </cylinder>
        </geometry>
        <surface>
          <friction>
            <ode>
              <mu>1</mu>
              <mu2>1</mu2>
              <fdir1>0 0 0</fdir1>
              <slip1>0</slip1>
              <slip2>0</slip2>
            </ode>
            <torsional>
              <coefficient>1</coefficient>
              <patch_radius>0</patch_radius>
              <surface_radius>0</surface_radius>
              <use_patch_radius>1</use_patch_radius>
              <ode>
                <slip>0</slip>
              </ode>
            </torsional>
          </friction>
          <bounce>
            <restitution_coefficient>0</restitution_coefficient>
            <threshold>1e+06</threshold>
          </bounce>
          <contact>
            <collide_without_contact>0</collide_without_contact>
            <collide_without_contact_bitmask>1</collide_without_contact_bitmask>
            <collide_bitmask>1</collide_bitmask>
            <ode>
              <soft_cfm>0</soft_cfm>
              <soft_erp>0.2</soft_erp>
              <kp>1e+13</kp>
              <kd>1</kd>
              <max_vel>0.01</max_vel>
              <min_depth>0</min_depth>
            </ode>
            <bullet>
              <split_impulse>1</split_impulse>
              <split_impulse_penetration_threshold>-0.01</split_impulse_penetration_threshold>
              <soft_cfm>0</soft_cfm>
              <soft_erp>0.2</soft_erp>
              <kp>1e+13</kp>
              <kd>1</kd>
            </bullet>
          </contact>
        </surface>
      </collision>
    </link>
    <link name='uav0/imu_link'>
      <pose>0 0 0 0 -0 0</pose>
      <inertial>
        <pose>0 0 0 0 -0 0</pose>
        <mass>0.015</mass>
        <inertia>
          <ixx>1e-05</ixx>
          <ixy>0</ixy>
          <ixz>0</ixz>
          <iyy>1e-05</iyy>
          <iyz>0</iyz>
          <izz>1e-05</izz>
        </inertia>
      </inertial>
      <self_collide>0</self_collide>
      <enable_wind>0</enable_wind>
      <kinematic>0</kinematic>
    </link>
    <joint name='gps0_joint' type='fixed'>
      <parent>base_link</parent>
      <child>gps0_link</child>
      <pose>0 0 0 0 -0 0</pose>
      <physics>
        <ode>
          <limit>
            <cfm>0</cfm>
            <erp>0.2</erp>
          </limit>
          <suspension>
            <cfm>0</cfm>
            <erp>0.2</erp>
          </suspension>
        </ode>
      </physics>
    </joint>
    <joint name='rotor_0_joint' type='revolute'>
      <parent>base_link</parent>
      <child>rotor_0</child>
      <pose>0 0 0 0 -0 0</pose>
      <axis>
        <xyz>0 0 1</xyz>
        <limit>
          <lower>-1e+16</lower>
          <upper>1e+16</upper>
          <effort>-1</effort>
          <velocity>-1</velocity>
        </limit>
        <dynamics>
          <spring_reference>0</spring_reference>
          <spring_stiffness>0</spring_stiffness>
          <damping>0</damping>
          <friction>0</friction>
        </dynamics>
      </axis>
      <physics>
        <ode>
          <limit>
            <cfm>0</cfm>
            <erp>0.2</erp>
          </limit>
          <suspension>
            <cfm>0</cfm>
            <erp>0.2</erp>
          </suspension>
        </ode>
      </physics>
    </joint>
    <joint name='rotor_1_joint' type='revolute'>
      <parent>base_link</parent>
      <child>rotor_1</child>
      <pose>0 0 0 0 -0 0</pose>
      <axis>
        <xyz>0 0 1</xyz>
        <limit>
          <lower>-1e+16</lower>
          <upper>1e+16</upper>
          <effort>-1</effort>
          <velocity>-1</velocity>
        </limit>
        <dynamics>
          <spring_reference>0</spring_reference>
          <spring_stiffness>0</spring_stiffness>
          <damping>0</damping>
          <friction>0</friction>
        </dynamics>
      </axis>
      <physics>
        <ode>
          <limit>
            <cfm>0</cfm>
            <erp>0.2</erp>
          </limit>
          <suspension>
            <cfm>0</cfm>
            <erp>0.2</erp>
          </suspension>
        </ode>
      </physics>
    </joint>
    <joint name='rotor_2_joint' type='revolute'>
      <parent>base_link</parent>
      <child>rotor_2</child>
      <pose>0 0 0 0 -0 0</pose>
      <axis>
        <xyz>0 0 1</xyz>
        <limit>
          <lower>-1e+16</lower>
          <upper>1e+16</upper>
          <effort>-1</effort>
          <velocity>-1</velocity>
        </limit>
        <dynamics>
          <spring_reference>0</spring_reference>
          <spring_stiffness>0</spring_stiffness>
          <damping>0</damping>
          <friction>0</friction>
        </dynamics>
      </axis>
      <physics>
        <ode>
          <limit>
            <cfm>0</cfm>
            <erp>0.2</erp>
          </limit>
          <suspension>
            <cfm>0</cfm>
            <erp>0.2</erp>
          </suspension>
        </ode>
      </physics>
    </joint>
    <joint name='rotor_3_joint' type='revolute'>
      <parent>base_link</parent>
      <child>rotor_3</child>
      <pose>0 0 0 0 -0 0</pose>
      <axis>
        <xyz>0 0 1</xyz>
        <limit>
          <lower>-1e+16</lower>
          <upper>1e+16</upper>
          <effort>-1</effort>
          <velocity>-1</velocity>
        </limit>
        <dynamics>
          <spring_reference>0</spring_reference>
          <spring_stiffness>0</spring_stiffness>
          <damping>0</damping>
          <friction>0</friction>
        </dynamics>
      </axis>
      <physics>
        <ode>
          <limit>
            <cfm>0</cfm>
            <erp>0.2</erp>
          </limit>
          <suspension>
            <cfm>0</cfm>
            <erp>0.2</erp>
          </suspension>
        </ode>
      </physics>
    </joint>
    <joint name='uav0/imu_joint' type='revolute'>
      <parent>base_link</parent>
      <child>uav0/imu_link</child>
      <pose>0 0 0 0 -0 0</pose>
      <axis>
        <xyz>1 0 0</xyz>
        <limit>
          <lower>0</lower>
          <upper>0</upper>
          <effort>0</effort>
          <velocity>0</velocity>
        </limit>
        <dynamics>
          <spring_reference>0</spring_reference>
          <spring_stiffness>0</spring_stiffness>
          <damping>0</damping>
          <friction>0</friction>
        </dynamics>
      </axis>
      <physics>
        <ode>
          <limit>
            <cfm>0</cfm>
            <erp>0.2</erp>
          </limit>
          <suspension>
            <cfm>0</cfm>
            <erp>0.2</erp>
          </suspension>
        </ode>
      </physics>
    </joint>
    <static>0</static>
    <allow_auto_disable>1</allow_auto_disable>
    <plugin name='back_left_motor_model' filename='libgazebo_motor_model.so'>
      <robotNamespace>uav0</robotNamespace>
      <jointName>rotor_1_joint</jointName>
      <linkName>rotor_1</linkName>
      <turningDirection>ccw</turningDirection>
      <timeConstantUp>0.0125</timeConstantUp>
      <timeConstantDown>0.025</timeConstantDown>
      <maxRotVelocity>1</maxRotVelocity>
      <motorConstant>12.68433</motorConstant>
      <momentConstant>0.016</momentConstant>
      <commandSubTopic>/gazebo/command/motor_speed</commandSubTopic>
      <motorNumber>1</motorNumber>
      <rotorDragCoefficient>0.1</rotorDragCoefficient>
      <rollingMomentCoefficient>1e-06</rollingMomentCoefficient>
      <motorSpeedPubTopic>/motor_speed/1</motorSpeedPubTopic>
      <rotorVelocitySlowdownSim>0.0159236</rotorVelocitySlowdownSim>
    </plugin>
    <plugin name='back_right_motor_model' filename='libgazebo_motor_model.so'>
      <robotNamespace>uav0</robotNamespace>
      <jointName>rotor_3_joint</jointName>
      <linkName>rotor_3</linkName>
      <turningDirection>cw</turningDirection>
      <timeConstantUp>0.0125</timeConstantUp>
      <timeConstantDown>0.025</timeConstantDown>
      <maxRotVelocity>1</maxRotVelocity>
      <motorConstant>12.68433</motorConstant>
      <momentConstant>0.016</momentConstant>
      <commandSubTopic>/gazebo/command/motor_speed</commandSubTopic>
      <motorNumber>3</motorNumber>
      <rotorDragCoefficient>0.1</rotorDragCoefficient>
      <rollingMomentCoefficient>1e-06</rollingMomentCoefficient>
      <motorSpeedPubTopic>/motor_speed/3</motorSpeedPubTopic>
      <rotorVelocitySlowdownSim>0.0159236</rotorVelocitySlowdownSim>
    </plugin>
    <plugin name='barometer_plugin' filename='libgazebo_barometer_plugin.so'>
      <robotNamespace>uav0</robotNamespace>
      <pubRate>50</pubRate>
      <baroTopic>/baro</baroTopic>
      <baroDriftPaPerSec>0</baroDriftPaPerSec>
    </plugin>
    <plugin name='front_left_motor_model' filename='libgazebo_motor_model.so'>
      <robotNamespace>uav0</robotNamespace>
      <jointName>rotor_2_joint</jointName>
      <linkName>rotor_2</linkName>
      <turningDirection>cw</turningDirection>
      <timeConstantUp>0.0125</timeConstantUp>
      <timeConstantDown>0.025</timeConstantDown>
      <maxRotVelocity>1</maxRotVelocity>
      <motorConstant>12.68433</motorConstant>
      <momentConstant>0.016</momentConstant>
      <commandSubTopic>/gazebo/command/motor_speed</commandSubTopic>
      <motorNumber>2</motorNumber>
      <rotorDragCoefficient>0.1</rotorDragCoefficient>
      <rollingMomentCoefficient>1e-06</rollingMomentCoefficient>
      <motorSpeedPubTopic>/motor_speed/2</motorSpeedPubTopic>
      <rotorVelocitySlowdownSim>0.0159236</rotorVelocitySlowdownSim>
    </plugin>
    <plugin name='front_right_motor_model' filename='libgazebo_motor_model.so'>
      <robotNamespace>uav0</robotNamespace>
      <jointName>rotor_0_joint</jointName>
      <linkName>rotor_0</linkName>
      <turningDirection>ccw</turningDirection>
      <timeConstantUp>0.0125</timeConstantUp>
      <timeConstantDown>0.025</timeConstantDown>
      <maxRotVelocity>1</maxRotVelocity>
      <motorConstant>12.68433</motorConstant>
      <momentConstant>0.016</momentConstant>
      <commandSubTopic>/gazebo/command/motor_speed</commandSubTopic>
      <motorNumber>0</motorNumber>
      <rotorDragCoefficient>0.1</rotorDragCoefficient>
      <rollingMomentCoefficient>1e-06</rollingMomentCoefficient>
      <motorSpeedPubTopic>/motor_speed/0</motorSpeedPubTopic>
      <rotorVelocitySlowdownSim>0.0159236</rotorVelocitySlowdownSim>
    </plugin>
    <plugin name='groundtruth_plugin' filename='libgazebo_groundtruth_plugin.so'>
      <robotNamespace>uav0</robotNamespace>
      <homeLatitude>0.0</homeLatitude>
      <homeLongitude>0.0</homeLongitude>
      <homeAltitude>0.0</homeAltitude>
    </plugin>
    <plugin name='magnetometer_plugin' filename='libMRSGazeboMagnetometerPlugin.so'>
      <robotNamespace>uav0</robotNamespace>
      <pubRate>100</pubRate>
      <noiseDensity>0.0004</noiseDensity>
      <randomWalk>6.4e-06</randomWalk>
      <biasCorrelationTime>600</biasCorrelationTime>
      <magTopic>/mag</magTopic>
    </plugin>
    <plugin name='mavlink_interface' filename='libgazebo_mavlink_interface.so'>
      <robotNamespace>uav0</robotNamespace>
      <imuSubTopic>/imu</imuSubTopic>
      <magSubTopic>/mag</magSubTopic>
      <baroSubTopic>/baro</baroSubTopic>
      <mavlink_addr>INADDR_ANY</mavlink_addr>
      <mavlink_udp_port>14560</mavlink_udp_port>
      <mavlink_tcp_port>4560</mavlink_tcp_port>
      <serialEnabled>0</serialEnabled>
      <serialDevice>/dev/ttyACM0</serialDevice>
      <baudRate>921600</baudRate>
      <qgc_addr>INADDR_ANY</qgc_addr>
      <qgc_udp_port>14550</qgc_udp_port>
      <sdk_addr>INADDR_ANY</sdk_addr>
      <sdk_udp_port>14540</sdk_udp_port>
      <hil_mode>0</hil_mode>
      <hil_state_level>0</hil_state_level>
      <vehicle_is_tailsitter>0</vehicle_is_tailsitter>
      <send_vision_estimation>0</send_vision_estimation>
      <send_odometry>0</send_odometry>
      <enable_lockstep>1</enable_lockstep>
      <use_tcp>1</use_tcp>
      <motorSpeedCommandPubTopic>/gazebo/command/motor_speed</motorSpeedCommandPubTopic>
      <control_channels>
        <channel name='rotor1'>
          <input_index>0</input_index>
          <input_offset>0</input_offset>
          <input_scaling>1</input_scaling>
          <zero_position_disarmed>0</zero_position_disarmed>
          <zero_position_armed>0.15</zero_position_armed>
          <joint_control_type>velocity</joint_control_type>
        </channel>
        <channel name='rotor2'>
          <input_index>1</input_index>
          <input_offset>0</input_offset>
          <input_scaling>1</input_scaling>
          <zero_position_disarmed>0</zero_position_disarmed>
          <zero_position_armed>0.15</zero_position_armed>
          <joint_control_type>velocity</joint_control_type>
        </channel>
        <channel name='rotor3'>
          <input_index>2</input_index>
          <input_offset>0</input_offset>
          <input_scaling>1</input_scaling>
          <zero_position_disarmed>0</zero_position_disarmed>
          <zero_position_armed>0.15</zero_position_armed>
          <joint_control_type>velocity</joint_control_type>
        </channel>
        <channel name='rotor4'>
          <input_index>3</input_index>
          <input_offset>0</input_offset>
          <input_scaling>1</input_scaling>
          <zero_position_disarmed>0</zero_position_disarmed>
          <zero_position_armed>0.15</zero_position_armed>
          <joint_control_type>velocity</joint_control_type>
        </channel>
        <channel name='rotor5'>
          <input_index>4</input_index>
          <input_offset>0</input_offset>
          <input_scaling>1</input_scaling>
          <zero_position_disarmed>0</zero_position_disarmed>
          <zero_position_armed>0.15</zero_position_armed>
          <joint_control_type>velocity</joint_control_type>
        </channel>
        <channel name='rotor6'>
          <input_index>5</input_index>
          <input_offset>0</input_offset>
          <input_scaling>1</input_scaling>
          <zero_position_disarmed>0</zero_position_disarmed>
          <zero_position_armed>0.15</zero_position_armed>
          <joint_control_type>velocity</joint_control_type>
        </channel>
        <channel name='rotor7'>
          <input_index>6</input_index>
          <input_offset>0</input_offset>
          <input_scaling>1</input_scaling>
          <zero_position_disarmed>0</zero_position_disarmed>
          <zero_position_armed>0.15</zero_position_armed>
          <joint_control_type>velocity</joint_control_type>
        </channel>
        <channel name='rotor8'>
          <input_index>7</input_index>
          <input_offset>0</input_offset>
          <input_scaling>1</input_scaling>
          <zero_position_disarmed>0</zero_position_disarmed>
          <zero_position_armed>0.15</zero_position_armed>
          <joint_control_type>velocity</joint_control_type>
        </channel>
      </control_channels>
    </plugin>
    <plugin name='rosbag' filename='libgazebo_multirotor_base_plugin.so'>
      <robotNamespace>uav0</robotNamespace>
      <linkName>base_link</linkName>
      <rotorVelocitySlowdownSim>0.0159236</rotorVelocitySlowdownSim>
    </plugin>
    <plugin name='rotors_gazebo_imu_plugin' filename='libgazebo_imu_plugin.so'>
      <robotNamespace>uav0</robotNamespace>
      <linkName>uav0/imu_link</linkName>
      <imuTopic>/imu</imuTopic>
      <gyroscopeNoiseDensity>0.00018665</gyroscopeNoiseDensity>
      <gyroscopeRandomWalk>3.8785e-05</gyroscopeRandomWalk>
      <gyroscopeBiasCorrelationTime>1000.0</gyroscopeBiasCorrelationTime>
      <gyroscopeTurnOnBiasSigma>0.0087</gyroscopeTurnOnBiasSigma>
      <accelerometerNoiseDensity>0.00186</accelerometerNoiseDensity>
      <accelerometerRandomWalk>0.006</accelerometerRandomWalk>
      <accelerometerBiasCorrelationTime>300.0</accelerometerBiasCorrelationTime>
      <accelerometerTurnOnBiasSigma>0.196</accelerometerTurnOnBiasSigma>
    </plugin>
  </model>
</sdf>
